Traceback (most recent call last):
  File "/opt/anaconda3/envs/airflow_env/lib/python3.8/site-packages/psutil/_common.py", line 441, in wrapper
    ret = self._cache[fun]
AttributeError: _cache

During handling of the above exception, another exception occurred:

Traceback (most recent call last):
  File "/opt/anaconda3/envs/airflow_env/lib/python3.8/site-packages/psutil/_psosx.py", line 343, in wrapper
    return fun(self, *args, **kwargs)
  File "/opt/anaconda3/envs/airflow_env/lib/python3.8/site-packages/psutil/_common.py", line 444, in wrapper
    return fun(self)
  File "/opt/anaconda3/envs/airflow_env/lib/python3.8/site-packages/psutil/_psosx.py", line 370, in _get_kinfo_proc
    ret = cext.proc_kinfo_oneshot(self.pid)
ProcessLookupError: [Errno 3] assume no such process (originated from sysctl(kinfo_proc), len == 0)

During handling of the above exception, another exception occurred:

Traceback (most recent call last):
  File "/opt/anaconda3/envs/airflow_env/lib/python3.8/site-packages/psutil/__init__.py", line 361, in _init
    self.create_time()
  File "/opt/anaconda3/envs/airflow_env/lib/python3.8/site-packages/psutil/__init__.py", line 717, in create_time
    self._create_time = self._proc.create_time()
  File "/opt/anaconda3/envs/airflow_env/lib/python3.8/site-packages/psutil/_psosx.py", line 343, in wrapper
    return fun(self, *args, **kwargs)
  File "/opt/anaconda3/envs/airflow_env/lib/python3.8/site-packages/psutil/_psosx.py", line 468, in create_time
    return self._get_kinfo_proc()[kinfo_proc_map['ctime']]
  File "/opt/anaconda3/envs/airflow_env/lib/python3.8/site-packages/psutil/_psosx.py", line 348, in wrapper
    raise NoSuchProcess(self.pid, self._name)
psutil.NoSuchProcess: process no longer exists (pid=5863)

During handling of the above exception, another exception occurred:

Traceback (most recent call last):
  File "/opt/anaconda3/envs/airflow_env/bin/airflow", line 8, in <module>
    sys.exit(main())
  File "/opt/anaconda3/envs/airflow_env/lib/python3.8/site-packages/airflow/__main__.py", line 48, in main
    args.func(args)
  File "/opt/anaconda3/envs/airflow_env/lib/python3.8/site-packages/airflow/cli/cli_parser.py", line 48, in command
    return func(*args, **kwargs)
  File "/opt/anaconda3/envs/airflow_env/lib/python3.8/site-packages/airflow/utils/cli.py", line 92, in wrapper
    return f(*args, **kwargs)
  File "/opt/anaconda3/envs/airflow_env/lib/python3.8/site-packages/airflow/cli/commands/webserver_command.py", line 482, in webserver
    monitor_gunicorn(gunicorn_master_proc.pid)
  File "/opt/anaconda3/envs/airflow_env/lib/python3.8/site-packages/airflow/cli/commands/webserver_command.py", line 447, in monitor_gunicorn
    GunicornMonitor(
  File "/opt/anaconda3/envs/airflow_env/lib/python3.8/site-packages/airflow/cli/commands/webserver_command.py", line 205, in start
    self._wait_until_true(
  File "/opt/anaconda3/envs/airflow_env/lib/python3.8/site-packages/airflow/cli/commands/webserver_command.py", line 153, in _wait_until_true
    while not fn():
  File "/opt/anaconda3/envs/airflow_env/lib/python3.8/site-packages/airflow/cli/commands/webserver_command.py", line 206, in <lambda>
    lambda: self.num_workers_expected == self._get_num_workers_running(),
  File "/opt/anaconda3/envs/airflow_env/lib/python3.8/site-packages/airflow/cli/commands/webserver_command.py", line 147, in _get_num_workers_running
    workers = psutil.Process(self.gunicorn_master_proc.pid).children()
  File "/opt/anaconda3/envs/airflow_env/lib/python3.8/site-packages/psutil/__init__.py", line 332, in __init__
    self._init(pid)
  File "/opt/anaconda3/envs/airflow_env/lib/python3.8/site-packages/psutil/__init__.py", line 373, in _init
    raise NoSuchProcess(pid, msg='process PID not found')
psutil.NoSuchProcess: process PID not found (pid=5863)
